Workbook

Sheet Dashboard
A1: HARIOM LOGISTICS — DASHBOARD
A3: Total Trips | B3: =COUNTA('Trip Log'!A4:A502)
A5: Total Freight (All Trips) | B5: =SUM('Trip Log'!I4:I502)
A7: Outstanding Owner Balance | B7: =SUM('Owner Ledger'!H5:H9)
A9: Pending Freight Bills | B9: =SUM('Freight Bills'!J5:J34)
A11: Trips Missing PAHUNCH | B11: =COUNTIFS('Trip Log'!P4:P502,"",'Trip Log'!I4:I502,">0")
A13: Trips Missing Bill Ref | B13: =COUNTIFS('Trip Log'!Q4:Q502,"",'Trip Log'!I4:I502,">0")
A16: Last updated | B16: 46201.519
A19: HOW TO USE
A20: 1. Trip Log: pick Party, Destination & Truck from dropdowns — Owner, Commission & Balance auto-fill.
A21: 2. Freight Bills: set Trip Bill Ref (e.g. 11, 4 EPOD) — BILL AMOUNT auto-sums matching trips.
A22: 3. Payments: always select Owner so Owner Ledger stays accurate.
A23: 4. Master Data: add new parties, trucks, or destinations here — dropdowns update automatically.
A24: 5. Yellow rows = PAHUNCH overdue. Red rows = Bill Ref missing on a trip with freight.

Sheet Trip Log
A1: HARIOM LOGISTICS — TRIP LOG
A2: Tip: Select Party, Destination & Truck from dropdowns. Owner, Commission & Balance auto-calculate. Yellow = PAHUNCH overdue. Red = Bill Ref missing.
A3: LR No | B3: Date | C3: Sold To Party | D3: Destination | E3: Truck No | F3: Owner Name | G3: Quantity | H3: Rate | I3: Freight | J3: Diesel | K3: Cash | L3: Total Advance | M3: Commission | N3: Munsiyana | O3: Balance | P3: PAHUNCH | Q3: Bill Ref | R3: Payment Date | S3: Payment Amt | T3: Particulars
A4: 2 | B4: 46172.087 | C4: TAMEER TRADERS | D4: SHAHJHANPUR | E4: UP25JT8804 | F4: =IF(E4="","",XLOOKUP(E4,'Master Data'!$E$5:$E$15,'Master Data'!$F$5:$F$15,"")) | G4: 13 | H4: 468 | I4: =IF(OR(G4="",H4=""),"",G4*H4) | L4: =IF(I4="","",I4-IF(J4="",0,J4)-IF(K4="",0,K4)) | M4: =IF(E4="","",XLOOKUP(E4,'Master Data'!$E$5:$E$15,'Master Data'!$G$5:$G$15,0)) | N4: =IF(E4="","",XLOOKUP(E4,'Master Data'!$E$5:$E$15,'Master Data'!$H$5:$H$15,0)) | O4: =IF(L4="","",L4-M4-N4) | P4: YES | Q4: 1 EPOD
A5: 4 | B5: 46172.545 | C5: JUNEJA TRADERS | D5: BUDAUN | E5: UP25CT2572 | F5: =IF(E5="","",XLOOKUP(E5,'Master Data'!$E$5:$E$15,'Master Data'!$F$5:$F$15,"")) | G5: 20 | H5: 364 | I5: =IF(OR(G5="",H5=""),"",G5*H5) | L5: =IF(I5="","",I5-IF(J5="",0,J5)-IF(K5="",0,K5)) | M5: =IF(E5="","",XLOOKUP(E5,'Master Data'!$E$5:$E$15,'Master Data'!$G$5:$G$15,0)) | N5: =IF(E5="","",XLOOKUP(E5,'Master Data'!$E$5:$E$15,'Master Data'!$H$5:$H$15,0)) | O5: =IF(L5="","",L5-M5-N5) | P5: YES | Q5: 4 EPOD
A6: 3 | B6: 46172.129 | C6: JAI BHARAT ENTERPRISES (SIS) | D6: SHAHBAZ NAGAR | E6: UP25JT8802 | F6: =IF(E6="","",XLOOKUP(E6,'Master Data'!$E$5:$E$15,'Master Data'!$F$5:$F$15,"")) | G6: 13 | H6: 367 | I6: =IF(OR(G6="",H6=""),"",G6*H6) | L6: =IF(I6="","",I6-IF(J6="",0,J6)-IF(K6="",0,K6)) | M6: =IF(E6="","",XLOOKUP(E6,'Master Data'!$E$5:$E$15,'Master Data'!$G$5:$G$15,0)) | N6: =IF(E6="","",XLOOKUP(E6,'Master Data'!$E$5:$E$15,'Master Data'!$H$5:$H$15,0)) | O6: =IF(L6="","",L6-M6-N6) | P6: YES | Q6: 1 EPOD
A7: 1 | B7: 46172.629 | C7: RAFI KHAN BUILDING MATERIAL | D7: SHAHBAD (HARDOI) | E7: UP25JT8803 | F7: =IF(E7="","",XLOOKUP(E7,'Master Data'!$E$5:$E$15,'Master Data'!$F$5:$F$15,"")) | G7: 13 | H7: 456 | I7: =IF(OR(G7="",H7=""),"",G7*H7) | L7: =IF(I7="","",I7-IF(J7="",0,J7)-IF(K7="",0,K7)) | M7: =IF(E7="","",XLOOKUP(E7,'Master Data'!$E$5:$E$15,'Master Data'!$G$5:$G$15,0)) | N7: =IF(E7="","",XLOOKUP(E7,'Master Data'!$E$5:$E$15,'Master Data'!$H$5:$H$15,0)) | O7: =IF(L7="","",L7-M7-N7) | Q7: 3
A8: 5 | B8: 46173.671 | C8: JAI BHARAT ENTERPRISES (SIS) | D8: KATRA | E8: UP25JT8802 | F8: =IF(E8="","",XLOOKUP(E8,'Master Data'!$E$5:$E$15,'Master Data'!$F$5:$F$15,"")) | G8: 13 | H8: 225 | I8: =IF(OR(G8="",H8=""),"",G8*H8) | L8: =IF(I8="","",I8-IF(J8="",0,J8)-IF(K8="",0,K8)) | M8: =IF(E8="","",XLOOKUP(E8,'Master Data'!$E$5:$E$15,'Master Data'!$G$5:$G$15,0)) | N8: =IF(E8="","",XLOOKUP(E8,'Master Data'!$E$5:$E$15,'Master Data'!$H$5:$H$15,0)) | O8: =IF(L8="","",L8-M8-N8) | P8: YES | Q8: 1 EPOD
A9: 6 | B9: 46173.671 | C9: SHIV TRADING COMPANY | D9: NIGOHI | E9: UP25JT8804 | F9: =IF(E9="","",XLOOKUP(E9,'Master Data'!$E$5:$E$15,'Master Data'!$F$5:$F$15,"")) | G9: 13 | H9: 360 | I9: =IF(OR(G9="",H9=""),"",G9*H9) | L9: =IF(I9="","",I9-IF(J9="",0,J9)-IF(K9="",0,K9)) | M9: =IF(E9="","",XLOOKUP(E9,'Master Data'!$E$5:$E$15,'Master Data'!$G$5:$G$15,0)) | N9: =IF(E9="","",XLOOKUP(E9,'Master Data'!$E$5:$E$15,'Master Data'!$H$5:$H$15,0)) | O9: =IF(L9="","",L9-M9-N9) | P9: YES | Q9: 2 EPOD
A10: 7 | B10: 46173.754 | C10: BHARAT FERTILIZERS (SIS) | D10: KATRA | E10: UP25JT8803 | F10: =IF(E10="","",XLOOKUP(E10,'Master Data'!$E$5:$E$15,'Master Data'!$F$5:$F$15,"")) | G10: 13 | H10: 225 | I10: =IF(OR(G10="",H10=""),"",G10*H10) | L10: =IF(I10="","",I10-IF(J10="",0,J10)-IF(K10="",0,K10)) | M10: =IF(E10="","",XLOOKUP(E10,'Master Data'!$E$5:$E$15,'Master Data'!$G$5:$G$15,0)) | N10: =IF(E10="","",XLOOKUP(E10,'Master Data'!$E$5:$E$15,'Master Data'!$H$5:$H$15,0)) | O10: =IF(L10="","",L10-M10-N10) | P10: YES | Q10: 2 EPOD
A11: 8 | B11: 46174.755 | C11: SHYAM NARAIN RAMESH KUMAR AND SONS | D11: BHOJIPURA | E11: UP25CT2572 | F11: =IF(E11="","",XLOOKUP(E11,'Master Data'!$E$5:$E$15,'Master Data'!$F$5:$F$15,"")) | G11: 10 | H11: 321 | I11: =IF(OR(G11="",H11=""),"",G11*H11) | L11: =IF(I11="","",I11-IF(J11="",0,J11)-IF(K11="",0,K11)) | M11: =IF(E11="","",XLOOKUP(E11,'Master Data'!$E$5:$E$15,'Master Data'!$G$5:$G$15,0)) | N11: =IF(E11="","",XLOOKUP(E11,'Master Data'!$E$5:$E$15,'Master Data'!$H$5:$H$15,0)) | O11: =IF(L11="","",L11-M11-N11) | Q11: 6
A12: 9 | B12: 46174.754 | C12: SHYAM NARAIN RAMESH KUMAR AND SONS | D12: BHOJIPURA | E12: UP25CT2572 | F12: =IF(E12="","",XLOOKUP(E12,'Master Data'!$E$5:$E$15,'Master Data'!$F$5:$F$15,"")) | G12: 15 | H12: 321 | I12: =IF(OR(G12="",H12=""),"",G12*H12) | L12: =IF(I12="","",I12-IF(J12="",0,J12)-IF(K12="",0,K12)) | M12: =IF(E12="","",XLOOKUP(E12,'Master Data'!$E$5:$E$15,'Master Data'!$G$5:$G$15,0)) | N12: =IF(E12="","",XLOOKUP(E12,'Master Data'!$E$5:$E$15,'Master Data'!$H$5:$H$15,0)) | O12: =IF(L12="","",L12-M12-N12) | Q12: 6
A13: 10 | B13: 46174.796 | C13: GAFFAR CEMENT STORE | D13: SHAHBAD (HARDOI) | E13: UP25CT7099 | F13: =IF(E13="","",XLOOKUP(E13,'Master Data'!$E$5:$E$15,'Master Data'!$F$5:$F$15,"")) | G13: 30 | H13: 293 | I13: =IF(OR(G13="",H13=""),"",G13*H13) | L13: =IF(I13="","",I13-IF(J13="",0,J13)-IF(K13="",0,K13)) | M13: =IF(E13="","",XLOOKUP(E13,'Master Data'!$E$5:$E$15,'Master Data'!$G$5:$G$15,0)) | N13: =IF(E13="","",XLOOKUP(E13,'Master Data'!$E$5:$E$15,'Master Data'!$H$5:$H$15,0)) | O13: =IF(L13="","",L13-M13-N13) | P13: YES | Q13: 1 EPOD
A14: 11 | B14: 46175.088 | C14: MALBROS INTERNATIONAL PVT LTD | D14: KHUDAGANJ (NP) | E14: UP25DT1881 | F14: =IF(E14="","",XLOOKUP(E14,'Master Data'!$E$5:$E$15,'Master Data'!$F$5:$F$15,"")) | G14: 35 | H14: 175 | I14: =IF(OR(G14="",H14=""),"",G14*H14) | L14: =IF(I14="","",I14-IF(J14="",0,J14)-IF(K14="",0,K14)) | M14: =IF(E14="","",XLOOKUP(E14,'Master Data'!$E$5:$E$15,'Master Data'!$G$5:$G$15,0)) | N14: =IF(E14="","",XLOOKUP(E14,'Master Data'!$E$5:$E$15,'Master Data'!$H$5:$H$15,0)) | O14: =IF(L14="","",L14-M14-N14) | Q14: 3
A15: 15 | B15: 46175.046 | C15: GAFFAR CEMENT STORE | D15: SHAHBAD (HARDOI) | E15: UP25JT8803 | F15: =IF(E15="","",XLOOKUP(E15,'Master Data'!$E$5:$E$15,'Master Data'!$F$5:$F$15,"")) | G15: 13 | H15: 413 | I15: =IF(OR(G15="",H15=""),"",G15*H15) | L15: =IF(I15="","",I15-IF(J15="",0,J15)-IF(K15="",0,K15)) | M15: =IF(E15="","",XLOOKUP(E15,'Master Data'!$E$5:$E$15,'Master Data'!$G$5:$G$15,0)) | N15: =IF(E15="","",XLOOKUP(E15,'Master Data'!$E$5:$E$15,'Master Data'!$H$5:$H$15,0)) | O15: =IF(L15="","",L15-M15-N15) | P15: YES | Q15: 1 EPOD
A16: 16 | B16: 46175.088 | C16: GOEL DISTRIBUTORS | D16: BAREILLY | E16: UP25DT5668 | F16: =IF(E16="","",XLOOKUP(E16,'Master Data'!$E$5:$E$15,'Master Data'!$F$5:$F$15,"")) | G16: 10 | H16: 368 | I16: =IF(OR(G16="",H16=""),"",G16*H16) | L16: =IF(I16="","",I16-IF(J16="",0,J16)-IF(K16="",0,K16)) | M16: =IF(E16="","",XLOOKUP(E16,'Master Data'!$E$5:$E$15,'Master Data'!$G$5:$G$15,0)) | N16: =IF(E16="","",XLOOKUP(E16,'Master Data'!$E$5:$E$15,'Master Data'!$H$5:$H$15,0)) | O16: =IF(L16="","",L16-M16-N16) | Q16: 3
A17: 17 | B17: 46175.088 | C17: GOEL DISTRIBUTORS | D17: BAREILLY | E17: UP25DT5668 | F17: =IF(E17="","",XLOOKUP(E17,'Master Data'!$E$5:$E$15,'Master Data'!$F$5:$F$15,"")) | G17: 10 | H17: 368 | I17: =IF(OR(G17="",H17=""),"",G17*H17) | L17: =IF(I17="","",I17-IF(J17="",0,J17)-IF(K17="",0,K17)) | M17: =IF(E17="","",XLOOKUP(E17,'Master Data'!$E$5:$E$15,'Master Data'!$G$5:$G$15,0)) | N17: =IF(E17="","",XLOOKUP(E17,'Master Data'!$E$5:$E$15,'Master Data'!$H$5:$H$15,0)) | O17: =IF(L17="","",L17-M17-N17)
A18: 18 | B18: 46175.796 | C18: TAMEER TRADERS | D18: KATRA | E18: UP25JT8802 | F18: =IF(E18="","",XLOOKUP(E18,'Master Data'!$E$5:$E$15,'Master Data'!$F$5:$F$15,"")) | G18: 13 | H18: 225 | I18: =IF(OR(G18="",H18=""),"",G18*H18) | L18: =IF(I18="","",I18-IF(J18="",0,J18)-IF(K18="",0,K18)) | M18: =IF(E18="","",XLOOKUP(E18,'Master Data'!$E$5:$E$15,'Master Data'!$G$5:$G$15,0)) | N18: =IF(E18="","",XLOOKUP(E18,'Master Data'!$E$5:$E$15,'Master Data'!$H$5:$H$15,0)) | O18: =IF(L18="","",L18-M18-N18) | P18: YES | Q18: 4 EPOD
A19: 19 | B19: 46175.797 | C19: DUA AGENCIES | D19: NIGOHI | E19: UP25JT8804 | F19: =IF(E19="","",XLOOKUP(E19,'Master Data'!$E$5:$E$15,'Master Data'!$F$5:$F$15,"")) | G19: 13 | H19: 325 | I19: =IF(OR(G19="",H19=""),"",G19*H19) | L19: =IF(I19="","",I19-IF(J19="",0,J19)-IF(K19="",0,K19)) | M19: =IF(E19="","",XLOOKUP(E19,'Master Data'!$E$5:$E$15,'Master Data'!$G$5:$G$15,0)) | N19: =IF(E19="","",XLOOKUP(E19,'Master Data'!$E$5:$E$15,'Master Data'!$H$5:$H$15,0)) | O19: =IF(L19="","",L19-M19-N19) | P19: YES | Q19: 4 EPOD
A20: 20 | B20: 46175.88 | C20: MITTAL FERTILIZERS | D20: FAREEDPUR | E20: UP25CT2572 | F20: =IF(E20="","",XLOOKUP(E20,'Master Data'!$E$5:$E$15,'Master Data'!$F$5:$F$15,"")) | G20: 10 | H20: 226 | I20: =IF(OR(G20="",H20=""),"",G20*H20) | L20: =IF(I20="","",I20-IF(J20="",0,J20)-IF(K20="",0,K20)) | M20: =IF(E20="","",XLOOKUP(E20,'Master Data'!$E$5:$E$15,'Master Data'!$G$5:$G$15,0)) | N20: =IF(E20="","",XLOOKUP(E20,'Master Data'!$E$5:$E$15,'Master Data'!$H$5:$H$15,0)) | O20: =IF(L20="","",L20-M20-N20) | P20: YES | Q20: 4 EPOD
A21: 21 | B21: 46175.921 | C21: MITTAL FERTILIZERS | D21: RAJAU PARASPUR | E21: UP25CT2572 | F21: =IF(E21="","",XLOOKUP(E21,'Master Data'!$E$5:$E$15,'Master Data'!$F$5:$F$15,"")) | G21: 6 | H21: 258 | I21: =IF(OR(G21="",H21=""),"",G21*H21) | L21: =IF(I21="","",I21-IF(J21="",0,J21)-IF(K21="",0,K21)) | M21: =IF(E21="","",XLOOKUP(E21,'Master Data'!$E$5:$E$15,'Master Data'!$G$5:$G$15,0)) | N21: =IF(E21="","",XLOOKUP(E21,'Master Data'!$E$5:$E$15,'Master Data'!$H$5:$H$15,0)) | O21: =IF(L21="","",L21-M21-N21) | Q21: 7 EPOD
A22: 22 | B22: 46175.921 | C22: MITTAL FERTILIZERS | D22: FAREEDPUR | E22: UP25CT2572 | F22: =IF(E22="","",XLOOKUP(E22,'Master Data'!$E$5:$E$15,'Master Data'!$F$5:$F$15,"")) | G22: 9 | H22: 226 | I22: =IF(OR(G22="",H22=""),"",G22*H22) | L22: =IF(I22="","",I22-IF(J22="",0,J22)-IF(K22="",0,K22)) | M22: =IF(E22="","",XLOOKUP(E22,'Master Data'!$E$5:$E$15,'Master Data'!$G$5:$G$15,0)) | N22: =IF(E22="","",XLOOKUP(E22,'Master Data'!$E$5:$E$15,'Master Data'!$H$5:$H$15,0)) | O22: =IF(L22="","",L22-M22-N22) | P22: YES | Q22: 4 EPOD
A23: 24 | B23: 46176.046 | C23: TAMEER TRADERS | D23: SHAHJHANPUR | E23: UP25JT8803 | F23: =IF(E23="","",XLOOKUP(E23,'Master Data'!$E$5:$E$15,'Master Data'!$F$5:$F$15,"")) | G23: 13 | H23: 423 | I23: =IF(OR(G23="",H23=""),"",G23*H23) | L23: =IF(I23="","",I23-IF(J23="",0,J23)-IF(K23="",0,K23)) | M23: =IF(E23="","",XLOOKUP(E23,'Master Data'!$E$5:$E$15,'Master Data'!$G$5:$G$15,0)) | N23: =IF(E23="","",XLOOKUP(E23,'Master Data'!$E$5:$E$15,'Master Data'!$H$5:$H$15,0)) | O23: =IF(L23="","",L23-M23-N23) | P23: YES | Q23: 1 EPOD
A24: 23 | B24: 46176.129 | C24: SHREE VASUNDHARA INFRAPROMOTERS | D24: RUDRAPUR | E24: UP25DT1881 | F24: =IF(E24="","",XLOOKUP(E24,'Master Data'!$E$5:$E$15,'Master Data'!$F$5:$F$15,"")) | G24: 35 | H24: 434 | I24: =IF(OR(G24="",H24=""),"",G24*H24) | L24: =IF(I24="","",I24-IF(J24="",0,J24)-IF(K24="",0,K24)) | M24: =IF(E24="","",XLOOKUP(E24,'Master Data'!$E$5:$E$15,'Master Data'!$G$5:$G$15,0)) | N24: =IF(E24="","",XLOOKUP(E24,'Master Data'!$E$5:$E$15,'Master Data'!$H$5:$H$15,0)) | O24: =IF(L24="","",L24-M24-N24) | Q24: 3
A25: 26 | B25: 46176.546 | C25: BHARAT FERTILIZERS (SIS) | D25: DADIYA | E25: UP25JT8804 | F25: =IF(E25="","",XLOOKUP(E25,'Master Data'!$E$5:$E$15,'Master Data'!$F$5:$F$15,"")) | G25: 13 | H25: 320 | I25: =IF(OR(G25="",H25=""),"",G25*H25) | L25: =IF(I25="","",I25-IF(J25="",0,J25)-IF(K25="",0,K25)) | M25: =IF(E25="","",XLOOKUP(E25,'Master Data'!$E$5:$E$15,'Master Data'!$G$5:$G$15,0)) | N25: =IF(E25="","",XLOOKUP(E25,'Master Data'!$E$5:$E$15,'Master Data'!$H$5:$H$15,0)) | O25: =IF(L25="","",L25-M25-N25) | P25: YES | Q25: 4 EPOD
A26: 25 | B26: 46176.546 | C26: JAI BHARAT ENTERPRISES (SIS) | D26: MOHAMMADI | E26: UP25JT8802 | F26: =IF(E26="","",XLOOKUP(E26,'Master Data'!$E$5:$E$15,'Master Data'!$F$5:$F$15,"")) | G26: 13 | H26: 510 | I26: =IF(OR(G26="",H26=""),"",G26*H26) | L26: =IF(I26="","",I26-IF(J26="",0,J26)-IF(K26="",0,K26)) | M26: =IF(E26="","",XLOOKUP(E26,'Master Data'!$E$5:$E$15,'Master Data'!$G$5:$G$15,0)) | N26: =IF(E26="","",XLOOKUP(E26,'Master Data'!$E$5:$E$15,'Master Data'!$H$5:$H$15,0)) | O26: =IF(L26="","",L26-M26-N26) | P26: YES | Q26: 4 EPOD
A27: 27 | B27: 46176.713 | C27: KANAN TRADERS | D27: KATHGODAM | E27: UP25CT7099 | F27: =IF(E27="","",XLOOKUP(E27,'Master Data'!$E$5:$E$15,'Master Data'!$F$5:$F$15,"")) | G27: 30 | H27: 586 | I27: =IF(OR(G27="",H27=""),"",G27*H27) | L27: =IF(I27="","",I27-IF(J27="",0,J27)-IF(K27="",0,K27)) | M27: =IF(E27="","",XLOOKUP(E27,'Master Data'!$E$5:$E$15,'Master Data'!$G$5:$G$15,0)) | N27: =IF(E27="","",XLOOKUP(E27,'Master Data'!$E$5:$E$15,'Master Data'!$H$5:$H$15,0)) | O27: =IF(L27="","",L27-M27-N27) | Q27: 3
A28: 28 | B28: 46176.838 | C28: SINGH TRADERS | D28: LAKHIMPUR | E28: UP25BT7464 | F28: =IF(E28="","",XLOOKUP(E28,'Master Data'!$E$5:$E$15,'Master Data'!$F$5:$F$15,"")) | G28: 30 | H28: 489 | I28: =IF(OR(G28="",H28=""),"",G28*H28) | L28: =IF(I28="","",I28-IF(J28="",0,J28)-IF(K28="",0,K28)) | M28: =IF(E28="","",XLOOKUP(E28,'Master Data'!$E$5:$E$15,'Master Data'!$G$5:$G$15,0)) | N28: =IF(E28="","",XLOOKUP(E28,'Master Data'!$E$5:$E$15,'Master Data'!$H$5:$H$15,0)) | O28: =IF(L28="","",L28-M28-N28) | P28: YES | Q28: 4 EPOD
A29: 29 | B29: 46177.629 | C29: BHARAT FERTILIZERS (SIS) | D29: BARKHERA JAIPAL | E29: UP25JT8802 | F29: =IF(E29="","",XLOOKUP(E29,'Master Data'!$E$5:$E$15,'Master Data'!$F$5:$F$15,"")) | G29: 13 | H29: 264 | I29: =IF(OR(G29="",H29=""),"",G29*H29) | L29: =IF(I29="","",I29-IF(J29="",0,J29)-IF(K29="",0,K29)) | M29: =IF(E29="","",XLOOKUP(E29,'Master Data'!$E$5:$E$15,'Master Data'!$G$5:$G$15,0)) | N29: =IF(E29="","",XLOOKUP(E29,'Master Data'!$E$5:$E$15,'Master Data'!$H$5:$H$15,0)) | O29: =IF(L29="","",L29-M29-N29) | P29: YES | Q29: 4 EPOD
A30: 30 | B30: 46177.671 | C30: BHARAT FERTILIZERS (SIS) | D30: TILHAR | E30: UP25JT8804 | F30: =IF(E30="","",XLOOKUP(E30,'Master Data'!$E$5:$E$15,'Master Data'!$F$5:$F$15,"")) | G30: 13 | H30: 264 | I30: =IF(OR(G30="",H30=""),"",G30*H30) | L30: =IF(I30="","",I30-IF(J30="",0,J30)-IF(K30="",0,K30)) | M30: =IF(E30="","",XLOOKUP(E30,'Master Data'!$E$5:$E$15,'Master Data'!$G$5:$G$15,0)) | N30: =IF(E30="","",XLOOKUP(E30,'Master Data'!$E$5:$E$15,'Master Data'!$H$5:$H$15,0)) | O30: =IF(L30="","",L30-M30-N30) | P30: YES | Q30: 4 EPOD
A31: 31 | B31: 46177.588 | C31: JAI BHARAT ENTERPRISES (SIS) | D31: KATRA | E31: UP25JT8803 | F31: =IF(E31="","",XLOOKUP(E31,'Master Data'!$E$5:$E$15,'Master Data'!$F$5:$F$15,"")) | G31: 13 | H31: 225 | I31: =IF(OR(G31="",H31=""),"",G31*H31) | L31: =IF(I31="","",I31-IF(J31="",0,J31)-IF(K31="",0,K31)) | M31: =IF(E31="","",XLOOKUP(E31,'Master Data'!$E$5:$E$15,'Master Data'!$G$5:$G$15,0)) | N31: =IF(E31="","",XLOOKUP(E31,'Master Data'!$E$5:$E$15,'Master Data'!$H$5:$H$15,0)) | O31: =IF(L31="","",L31-M31-N31) | P31: YES | Q31: 1 EPOD
A32: 32 | B32: 46177.796 | C32: S.P TRADERS | D32: PILIBHIT | E32: UP25CT2572 | F32: =IF(E32="","",XLOOKUP(E32,'Master Data'!$E$5:$E$15,'Master Data'!$F$5:$F$15,"")) | G32: 12 | H32: 429 | I32: =IF(OR(G32="",H32=""),"",G32*H32) | L32: =IF(I32="","",I32-IF(J32="",0,J32)-IF(K32="",0,K32)) | M32: =IF(E32="","",XLOOKUP(E32,'Master Data'!$E$5:$E$15,'Master Data'!$G$5:$G$15,0)) | N32: =IF(E32="","",XLOOKUP(E32,'Master Data'!$E$5:$E$15,'Master Data'!$H$5:$H$15,0)) | O32: =IF(L32="","",L32-M32-N32) | Q32: 5
A33: 33 | B33: 46177.796 | C33: S.P TRADERS | D33: PILIBHIT | E33: UP25CT2572 | F33: =IF(E33="","",XLOOKUP(E33,'Master Data'!$E$5:$E$15,'Master Data'!$F$5:$F$15,"")) | G33: 13 | H33: 429 | I33: =IF(OR(G33="",H33=""),"",G33*H33) | L33: =IF(I33="","",I33-IF(J33="",0,J33)-IF(K33="",0,K33)) | M33: =IF(E33="","",XLOOKUP(E33,'Master Data'!$E$5:$E$15,'Master Data'!$G$5:$G$15,0)) | N33: =IF(E33="","",XLOOKUP(E33,'Master Data'!$E$5:$E$15,'Master Data'!$H$5:$H$15,0)) | O33: =IF(L33="","",L33-M33-N33) | Q33: 5
A34: 37 | B34: 46178.63 | C34: GAFFAR CEMENT STORE | D34: TANDIYAWAN | E34: UP25CT2572 | F34: =IF(E34="","",XLOOKUP(E34,'Master Data'!$E$5:$E$15,'Master Data'!$F$5:$F$15,"")) | G34: 12.5 | H34: 490 | I34: =IF(OR(G34="",H34=""),"",G34*H34) | L34: =IF(I34="","",I34-IF(J34="",0,J34)-IF(K34="",0,K34)) | M34: =IF(E34="","",XLOOKUP(E34,'Master Data'!$E$5:$E$15,'Master Data'!$G$5:$G$15,0)) | N34: =IF(E34="","",XLOOKUP(E34,'Master Data'!$E$5:$E$15,'Master Data'!$H$5:$H$15,0)) | O34: =IF(L34="","",L34-M34-N34) | P34: YES | Q34: 4 EPOD
A35: 36 | B35: 46178.63 | C35: GAFFAR CEMENT STORE | D35: TANDIYAWAN | E35: UP25CT2572 | F35: =IF(E35="","",XLOOKUP(E35,'Master Data'!$E$5:$E$15,'Master Data'!$F$5:$F$15,"")) | G35: 12.5 | H35: 490 | I35: =IF(OR(G35="",H35=""),"",G35*H35) | L35: =IF(I35="","",I35-IF(J35="",0,J35)-IF(K35="",0,K35)) | M35: =IF(E35="","",XLOOKUP(E35,'Master Data'!$E$5:$E$15,'Master Data'!$G$5:$G$15,0)) | N35: =IF(E35="","",XLOOKUP(E35,'Master Data'!$E$5:$E$15,'Master Data'!$H$5:$H$15,0)) | O35: =IF(L35="","",L35-M35-N35) | P35: YES | Q35: 4 EPOD
A36: 38 | B36: 46179.504 | C36: SINGH TRADERS | D36: BAREILLY | E36: UP25DT1881 | F36: =IF(E36="","",XLOOKUP(E36,'Master Data'!$E$5:$E$15,'Master Data'!$F$5:$F$15,"")) | G36: 35 | H36: 278 | I36: =IF(OR(G36="",H36=""),"",G36*H36) | L36: =IF(I36="","",I36-IF(J36="",0,J36)-IF(K36="",0,K36)) | M36: =IF(E36="","",XLOOKUP(E36,'Master Data'!$E$5:$E$15,'Master Data'!$G$5:$G$15,0)) | N36: =IF(E36="","",XLOOKUP(E36,'Master Data'!$E$5:$E$15,'Master Data'!$H$5:$H$15,0)) | O36: =IF(L36="","",L36-M36-N36) | Q36: 3
A37: 39 | B37: 46179.838 | C37: MAURIA BUILDING MATERIAL | D37: SHERGARH (BLY) | E37: UP25BT7464 | F37: =IF(E37="","",XLOOKUP(E37,'Master Data'!$E$5:$E$15,'Master Data'!$F$5:$F$15,"")) | G37: 10 | H37: 383 | I37: =IF(OR(G37="",H37=""),"",G37*H37) | L37: =IF(I37="","",I37-IF(J37="",0,J37)-IF(K37="",0,K37)) | M37: =IF(E37="","",XLOOKUP(E37,'Master Data'!$E$5:$E$15,'Master Data'!$G$5:$G$15,0)) | N37: =IF(E37="","",XLOOKUP(E37,'Master Data'!$E$5:$E$15,'Master Data'!$H$5:$H$15,0)) | O37: =IF(L37="","",L37-M37-N37) | Q37: 5
A38: 40 | B38: 46179.838 | C38: MAURIA BUILDING MATERIAL | D38: SHERGARH (BLY) | E38: UP25BT7464 | F38: =IF(E38="","",XLOOKUP(E38,'Master Data'!$E$5:$E$15,'Master Data'!$F$5:$F$15,"")) | G38: 10 | H38: 383 | I38: =IF(OR(G38="",H38=""),"",G38*H38) | L38: =IF(I38="","",I38-IF(J38="",0,J38)-IF(K38="",0,K38)) | M38: =IF(E38="","",XLOOKUP(E38,'Master Data'!$E$5:$E$15,'Master Data'!$G$5:$G$15,0)) | N38: =IF(E38="","",XLOOKUP(E38,'Master Data'!$E$5:$E$15,'Master Data'!$H$5:$H$15,0)) | O38: =IF(L38="","",L38-M38-N38) | Q38: 5
A39: 41 | B39: 46179.838 | C39: MOHD. AYUB TRADERS | D39: MAVAI KAZIYAN | E39: UP25BT7464 | F39: =IF(E39="","",XLOOKUP(E39,'Master Data'!$E$5:$E$15,'Master Data'!$F$5:$F$15,"")) | G39: 10 | H39: 403 | I39: =IF(OR(G39="",H39=""),"",G39*H39) | L39: =IF(I39="","",I39-IF(J39="",0,J39)-IF(K39="",0,K39)) | M39: =IF(E39="","",XLOOKUP(E39,'Master Data'!$E$5:$E$15,'Master Data'!$G$5:$G$15,0)) | N39: =IF(E39="","",XLOOKUP(E39,'Master Data'!$E$5:$E$15,'Master Data'!$H$5:$H$15,0)) | O39: =IF(L39="","",L39-M39-N39) | Q39: 5
A40: 42 | B40: 46178.796 | C40: JAI BHARAT ENTERPRISES (SIS) | D40: BANDA | E40: UP25JT8803 | F40: =IF(E40="","",XLOOKUP(E40,'Master Data'!$E$5:$E$15,'Master Data'!$F$5:$F$15,"")) | G40: 13 | H40: 449 | I40: =IF(OR(G40="",H40=""),"",G40*H40) | L40: =IF(I40="","",I40-IF(J40="",0,J40)-IF(K40="",0,K40)) | M40: =IF(E40="","",XLOOKUP(E40,'Master Data'!$E$5:$E$15,'Master Data'!$G$5:$G$15,0)) | N40: =IF(E40="","",XLOOKUP(E40,'Master Data'!$E$5:$E$15,'Master Data'!$H$5:$H$15,0)) | O40: =IF(L40="","",L40-M40-N40) | Q40: 5
...

Sheet Owner Ledger
A1: HARIOM LOGISTICS — OWNER LEDGER
A2: Auto-calculated from Trip Log and Payments. Net Due = Balance Payable − Payments Made.
A4: Owner Name | B4: Total Trips | C4: Total Freight | D4: Total Commission | E4: Total Munsiyana | F4: Balance Payable | G4: Payments Made | H4: Net Due | I4: Trips w/o PAHUNCH | J4: Unbilled Trips
A5: ='Master Data'!J5 | B5: =IF(A5="","",COUNTIF('Trip Log'!$F$4:$F$502,A5)) | C5: =IF(A5="","",SUMIF('Trip Log'!$F$4:$F$502,A5,'Trip Log'!$I$4:$I$502)) | D5: =IF(A5="","",SUMIF('Trip Log'!$F$4:$F$502,A5,'Trip Log'!$M$4:$M$502)) | E5: =IF(A5="","",SUMIF('Trip Log'!$F$4:$F$502,A5,'Trip Log'!$N$4:$N$502)) | F5: =IF(A5="","",SUMIF('Trip Log'!$F$4:$F$502,A5,'Trip Log'!$O$4:$O$502)) | G5: =IF(A5="","",SUMIF(Payments!$E$4:$E$203,A5,Payments!$C$4:$C$203)) | H5: =IF(A5="","",F5-G5) | I5: =IF(A5="","",COUNTIFS('Trip Log'!$F$4:$F$502,A5,'Trip Log'!$P$4:$P$502,"")) | J5: =IF(A5="","",COUNTIFS('Trip Log'!$F$4:$F$502,A5,'Trip Log'!$Q$4:$Q$502,""))
A6: ='Master Data'!J6 | B6: =IF(A6="","",COUNTIF('Trip Log'!$F$4:$F$502,A6)) | C6: =IF(A6="","",SUMIF('Trip Log'!$F$4:$F$502,A6,'Trip Log'!$I$4:$I$502)) | D6: =IF(A6="","",SUMIF('Trip Log'!$F$4:$F$502,A6,'Trip Log'!$M$4:$M$502)) | E6: =IF(A6="","",SUMIF('Trip Log'!$F$4:$F$502,A6,'Trip Log'!$N$4:$N$502)) | F6: =IF(A6="","",SUMIF('Trip Log'!$F$4:$F$502,A6,'Trip Log'!$O$4:$O$502)) | G6: =IF(A6="","",SUMIF(Payments!$E$4:$E$203,A6,Payments!$C$4:$C$203)) | H6: =IF(A6="","",F6-G6) | I6: =IF(A6="","",COUNTIFS('Trip Log'!$F$4:$F$502,A6,'Trip Log'!$P$4:$P$502,"")) | J6: =IF(A6="","",COUNTIFS('Trip Log'!$F$4:$F$502,A6,'Trip Log'!$Q$4:$Q$502,""))
A7: ='Master Data'!J7 | B7: =IF(A7="","",COUNTIF('Trip Log'!$F$4:$F$502,A7)) | C7: =IF(A7="","",SUMIF('Trip Log'!$F$4:$F$502,A7,'Trip Log'!$I$4:$I$502)) | D7: =IF(A7="","",SUMIF('Trip Log'!$F$4:$F$502,A7,'Trip Log'!$M$4:$M$502)) | E7: =IF(A7="","",SUMIF('Trip Log'!$F$4:$F$502,A7,'Trip Log'!$N$4:$N$502)) | F7: =IF(A7="","",SUMIF('Trip Log'!$F$4:$F$502,A7,'Trip Log'!$O$4:$O$502)) | G7: =IF(A7="","",SUMIF(Payments!$E$4:$E$203,A7,Payments!$C$4:$C$203)) | H7: =IF(A7="","",F7-G7) | I7: =IF(A7="","",COUNTIFS('Trip Log'!$F$4:$F$502,A7,'Trip Log'!$P$4:$P$502,"")) | J7: =IF(A7="","",COUNTIFS('Trip Log'!$F$4:$F$502,A7,'Trip Log'!$Q$4:$Q$502,""))
A8: ='Master Data'!J8 | B8: =IF(A8="","",COUNTIF('Trip Log'!$F$4:$F$502,A8)) | C8: =IF(A8="","",SUMIF('Trip Log'!$F$4:$F$502,A8,'Trip Log'!$I$4:$I$502)) | D8: =IF(A8="","",SUMIF('Trip Log'!$F$4:$F$502,A8,'Trip Log'!$M$4:$M$502)) | E8: =IF(A8="","",SUMIF('Trip Log'!$F$4:$F$502,A8,'Trip Log'!$N$4:$N$502)) | F8: =IF(A8="","",SUMIF('Trip Log'!$F$4:$F$502,A8,'Trip Log'!$O$4:$O$502)) | G8: =IF(A8="","",SUMIF(Payments!$E$4:$E$203,A8,Payments!$C$4:$C$203)) | H8: =IF(A8="","",F8-G8) | I8: =IF(A8="","",COUNTIFS('Trip Log'!$F$4:$F$502,A8,'Trip Log'!$P$4:$P$502,"")) | J8: =IF(A8="","",COUNTIFS('Trip Log'!$F$4:$F$502,A8,'Trip Log'!$Q$4:$Q$502,""))
A9: ='Master Data'!J9 | B9: =IF(A9="","",COUNTIF('Trip Log'!$F$4:$F$502,A9)) | C9: =IF(A9="","",SUMIF('Trip Log'!$F$4:$F$502,A9,'Trip Log'!$I$4:$I$502)) | D9: =IF(A9="","",SUMIF('Trip Log'!$F$4:$F$502,A9,'Trip Log'!$M$4:$M$502)) | E9: =IF(A9="","",SUMIF('Trip Log'!$F$4:$F$502,A9,'Trip Log'!$N$4:$N$502)) | F9: =IF(A9="","",SUMIF('Trip Log'!$F$4:$F$502,A9,'Trip Log'!$O$4:$O$502)) | G9: =IF(A9="","",SUMIF(Payments!$E$4:$E$203,A9,Payments!$C$4:$C$203)) | H9: =IF(A9="","",F9-G9) | I9: =IF(A9="","",COUNTIFS('Trip Log'!$F$4:$F$502,A9,'Trip Log'!$P$4:$P$502,"")) | J9: =IF(A9="","",COUNTIFS('Trip Log'!$F$4:$F$502,A9,'Trip Log'!$Q$4:$Q$502,""))
A11: GRAND TOTAL | B11: =SUM(B5:B9) | C11: =SUM(C5:C9) | D11: =SUM(D5:D9) | E11: =SUM(E5:E9) | F11: =SUM(F5:F9) | G11: =SUM(G5:G9) | H11: =SUM(H5:H9) | I11: =SUM(I5:I9) | J11: =SUM(J5:J9)

Sheet Freight Bills
A1: HARIOM LOGISTICS — FREIGHT BILLS (Auto-calculated)
A2: Link each bill to a Trip Bill Ref to auto-sum freight from Trip Log. Compare BILL AMOUNT vs Original Amt. while setting up links.
A4: DATE | B4: BILL No. | C4: Trip Bill Ref | D4: BILL AMOUNT | E4: Original Amt. | F4: Trip Count | G4: EPOD STATUS | H4: PENDING Amt. | I4: PASS Amt. | J4: Balance Due | K4: Running Total | L4: BILL STATUS
A5: 46181 | B5: HO/JUN/01 | C5: 1 EPOD | D5: =IF(C5="","",SUMIF('Trip Log'!$Q$4:$Q$502,C5,'Trip Log'!$I$4:$I$502)) | E5: 36363 | F5: =IF(C5="","",COUNTIF('Trip Log'!$Q$4:$Q$502,C5)) | G5: YES | H5: =IF(D5="","",D5-IF(I5="",0,I5)) | J5: =IF(H5="","",H5) | K5: =IF(J5="",0,J5) | L5: PENDING
A6: 46185 | B6: HO/JUN/02 | C6: 2 EPOD | D6: =IF(C6="","",SUMIF('Trip Log'!$Q$4:$Q$502,C6,'Trip Log'!$I$4:$I$502)) | E6: 61342 | F6: =IF(C6="","",COUNTIF('Trip Log'!$Q$4:$Q$502,C6)) | G6: YES | H6: =IF(D6="","",D6-IF(I6="",0,I6)) | J6: =IF(H6="","",H6) | K6: =IF(J6="","",K5+J6) | L6: PENDING
A7: 46189 | B7: HO/JUN/03 | C7: 3 | D7: =IF(C7="","",SUMIF('Trip Log'!$Q$4:$Q$502,C7,'Trip Log'!$I$4:$I$502)) | E7: 148316 | F7: =IF(C7="","",COUNTIF('Trip Log'!$Q$4:$Q$502,C7)) | G7: NO | H7: =IF(D7="","",D7-IF(I7="",0,I7)) | J7: =IF(H7="","",H7) | K7: =IF(J7="","",K6+J7) | L7: PENDING
A8: 46189 | B8: HO/JUN/04 | C8: 4 EPOD | D8: =IF(C8="","",SUMIF('Trip Log'!$Q$4:$Q$502,C8,'Trip Log'!$I$4:$I$502)) | E8: 123885 | F8: =IF(C8="","",COUNTIF('Trip Log'!$Q$4:$Q$502,C8)) | G8: YES | H8: =IF(D8="","",D8-IF(I8="",0,I8)) | J8: =IF(H8="","",H8) | K8: =IF(J8="","",K7+J8) | L8: PENDING
A9: 46189 | B9: HO/JUN/05 | C9: 5 | D9: =IF(C9="","",SUMIF('Trip Log'!$Q$4:$Q$502,C9,'Trip Log'!$I$4:$I$502)) | E9: 146784 | F9: =IF(C9="","",COUNTIF('Trip Log'!$Q$4:$Q$502,C9)) | G9: NO | H9: =IF(D9="","",D9-IF(I9="",0,I9)) | J9: =IF(H9="","",H9) | K9: =IF(J9="","",K8+J9) | L9: PENDING
A10: 46191 | B10: HO/JUN/06 | C10: 6 | D10: =IF(C10="","",SUMIF('Trip Log'!$Q$4:$Q$502,C10,'Trip Log'!$I$4:$I$502)) | E10: 132430 | F10: =IF(C10="","",COUNTIF('Trip Log'!$Q$4:$Q$502,C10)) | G10: NO | H10: =IF(D10="","",D10-IF(I10="",0,I10)) | J10: =IF(H10="","",H10) | K10: =IF(J10="","",K9+J10) | L10: PENDING
A11: 46191 | B11: HO/JUN/07 | C11: 7 EPOD | D11: =IF(C11="","",SUMIF('Trip Log'!$Q$4:$Q$502,C11,'Trip Log'!$I$4:$I$502)) | E11: 169377 | F11: =IF(C11="","",COUNTIF('Trip Log'!$Q$4:$Q$502,C11)) | G11: YES | H11: =IF(D11="","",D11-IF(I11="",0,I11)) | J11: =IF(H11="","",H11) | K11: =IF(J11="","",K10+J11) | L11: PENDING
A12: 46197 | B12: HO/JUN/08 | C12: 8 EPOD | D12: =IF(C12="","",SUMIF('Trip Log'!$Q$4:$Q$502,C12,'Trip Log'!$I$4:$I$502)) | E12: 126860 | F12: =IF(C12="","",COUNTIF('Trip Log'!$Q$4:$Q$502,C12)) | G12: YES | H12: =IF(D12="","",D12-IF(I12="",0,I12)) | J12: =IF(H12="","",H12) | K12: =IF(J12="","",K11+J12) | L12: PENDING
A13: 46197 | B13: HO/JUN/09 | C13: 9 EPOD | D13: =IF(C13="","",SUMIF('Trip Log'!$Q$4:$Q$502,C13,'Trip Log'!$I$4:$I$502)) | E13: 200561 | F13: =IF(C13="","",COUNTIF('Trip Log'!$Q$4:$Q$502,C13)) | G13: YES | H13: =IF(D13="","",D13-IF(I13="",0,I13)) | J13: =IF(H13="","",H13) | K13: =IF(J13="","",K12+J13) | L13: PENDING
A14: 46198 | B14: HO/JUN/10 | C14: 10 | D14: =IF(C14="","",SUMIF('Trip Log'!$Q$4:$Q$502,C14,'Trip Log'!$I$4:$I$502)) | E14: 87000 | F14: =IF(C14="","",COUNTIF('Trip Log'!$Q$4:$Q$502,C14)) | G14: NO | H14: =IF(D14="","",D14-IF(I14="",0,I14)) | J14: =IF(H14="","",H14) | K14: =IF(J14="","",K13+J14) | L14: PENDING
A15: 46198 | B15: HO/JUN/11 | C15: 11 | D15: =IF(C15="","",SUMIF('Trip Log'!$Q$4:$Q$502,C15,'Trip Log'!$I$4:$I$502)) | E15: 222436 | F15: =IF(C15="","",COUNTIF('Trip Log'!$Q$4:$Q$502,C15)) | G15: NO | H15: =IF(D15="","",D15-IF(I15="",0,I15)) | J15: =IF(H15="","",H15) | K15: =IF(J15="","",K14+J15) | L15: PENDING
D16: =IF(C16="","",SUMIF('Trip Log'!$Q$4:$Q$502,C16,'Trip Log'!$I$4:$I$502)) | F16: =IF(C16="","",COUNTIF('Trip Log'!$Q$4:$Q$502,C16)) | H16: =IF(D16="","",D16-IF(I16="",0,I16)) | J16: =IF(H16="","",H16) | K16: =IF(J16="","",K15+J16)
D17: =IF(C17="","",SUMIF('Trip Log'!$Q$4:$Q$502,C17,'Trip Log'!$I$4:$I$502)) | F17: =IF(C17="","",COUNTIF('Trip Log'!$Q$4:$Q$502,C17)) | H17: =IF(D17="","",D17-IF(I17="",0,I17)) | J17: =IF(H17="","",H17) | K17: =IF(J17="","",K16+J17)
D18: =IF(C18="","",SUMIF('Trip Log'!$Q$4:$Q$502,C18,'Trip Log'!$I$4:$I$502)) | F18: =IF(C18="","",COUNTIF('Trip Log'!$Q$4:$Q$502,C18)) | H18: =IF(D18="","",D18-IF(I18="",0,I18)) | J18: =IF(H18="","",H18) | K18: =IF(J18="","",K17+J18)
D19: =IF(C19="","",SUMIF('Trip Log'!$Q$4:$Q$502,C19,'Trip Log'!$I$4:$I$502)) | F19: =IF(C19="","",COUNTIF('Trip Log'!$Q$4:$Q$502,C19)) | H19: =IF(D19="","",D19-IF(I19="",0,I19)) | J19: =IF(H19="","",H19) | K19: =IF(J19="","",K18+J19)
D20: =IF(C20="","",SUMIF('Trip Log'!$Q$4:$Q$502,C20,'Trip Log'!$I$4:$I$502)) | F20: =IF(C20="","",COUNTIF('Trip Log'!$Q$4:$Q$502,C20)) | H20: =IF(D20="","",D20-IF(I20="",0,I20)) | J20: =IF(H20="","",H20) | K20: =IF(J20="","",K19+J20)
D21: =IF(C21="","",SUMIF('Trip Log'!$Q$4:$Q$502,C21,'Trip Log'!$I$4:$I$502)) | F21: =IF(C21="","",COUNTIF('Trip Log'!$Q$4:$Q$502,C21)) | H21: =IF(D21="","",D21-IF(I21="",0,I21)) | J21: =IF(H21="","",H21) | K21: =IF(J21="","",K20+J21)
D22: =IF(C22="","",SUMIF('Trip Log'!$Q$4:$Q$502,C22,'Trip Log'!$I$4:$I$502)) | F22: =IF(C22="","",COUNTIF('Trip Log'!$Q$4:$Q$502,C22)) | H22: =IF(D22="","",D22-IF(I22="",0,I22)) | J22: =IF(H22="","",H22) | K22: =IF(J22="","",K21+J22)
D23: =IF(C23="","",SUMIF('Trip Log'!$Q$4:$Q$502,C23,'Trip Log'!$I$4:$I$502)) | F23: =IF(C23="","",COUNTIF('Trip Log'!$Q$4:$Q$502,C23)) | H23: =IF(D23="","",D23-IF(I23="",0,I23)) | J23: =IF(H23="","",H23) | K23: =IF(J23="","",K22+J23)
D24: =IF(C24="","",SUMIF('Trip Log'!$Q$4:$Q$502,C24,'Trip Log'!$I$4:$I$502)) | F24: =IF(C24="","",COUNTIF('Trip Log'!$Q$4:$Q$502,C24)) | H24: =IF(D24="","",D24-IF(I24="",0,I24)) | J24: =IF(H24="","",H24) | K24: =IF(J24="","",K23+J24)
D25: =IF(C25="","",SUMIF('Trip Log'!$Q$4:$Q$502,C25,'Trip Log'!$I$4:$I$502)) | F25: =IF(C25="","",COUNTIF('Trip Log'!$Q$4:$Q$502,C25)) | H25: =IF(D25="","",D25-IF(I25="",0,I25)) | J25: =IF(H25="","",H25) | K25: =IF(J25="","",K24+J25)
D26: =IF(C26="","",SUMIF('Trip Log'!$Q$4:$Q$502,C26,'Trip Log'!$I$4:$I$502)) | F26: =IF(C26="","",COUNTIF('Trip Log'!$Q$4:$Q$502,C26)) | H26: =IF(D26="","",D26-IF(I26="",0,I26)) | J26: =IF(H26="","",H26) | K26: =IF(J26="","",K25+J26)
D27: =IF(C27="","",SUMIF('Trip Log'!$Q$4:$Q$502,C27,'Trip Log'!$I$4:$I$502)) | F27: =IF(C27="","",COUNTIF('Trip Log'!$Q$4:$Q$502,C27)) | H27: =IF(D27="","",D27-IF(I27="",0,I27)) | J27: =IF(H27="","",H27) | K27: =IF(J27="","",K26+J27)
... D34: =IF(C34="","",SUMIF('Trip Log'!$Q$4:$Q$502,C34,'Trip Log'!$I$4:$I$502)) | F34: =IF(C34="","",COUNTIF('Trip Log'!$Q$4:$Q$502,C34)) | H34: =IF(D34="","",D34-IF(I34="",0,I34)) | J34: =IF(H34="","",H34) | K34: =IF(J34="","",K33+J34)
A37: TOTAL OUTSTANDING | J37: =SUM(J5:J34)
A39: Original Manual Bill Total (for reference) | E39: 1455354

Sheet Payments
A1: HARIOM LOGISTICS — PAYMENTS
A2: Record payments to truck owners. Select Owner from dropdown to auto-update Owner Ledger.
A3: SL. NO. | B3: Date | C3: Paid Amount | D3: Paid To (Name) | E3: Owner | F3: Particulars
A4: 1 | C4: 5000 | D4: RAKESH CHANDRA JI | F4: TRF BY PAPPU CHACHA
A5: 2 | C5: 5000 | D5: RAKESH CHANDRA JI | F5: TRF BY PAPPU CHACHA
A6: 3 | B6: 46196 | C6: 40000 | D6: ABDUL MALIK JI | E6: VINEET | F6: A/C TRF FROM A/C 9391 BY VINEET
A7: 4 | B7: 46196 | C7: 4000 | D7: RAKESH CHANDRA JI | F7: TRF BY PAPPU CHACHA
A8: 5 | C8: 15000 | D8: SHELANDRA | F8: 0919 GPAY TO A/C SONI SHARMA
B9: 46192 | C9: 5000 | D9: BABU BHAI | F9: GPAY BY PAPPU CHACHA

Sheet Statements
A1: HARIOM LOGISTICS — OWNER STATEMENT PDFs
A2: Generate monthly PDF statements per truck owner from Trip Log and Payments data.
A4: COMMAND | B4: python3 generate_owner_statements.py --month 2026-06
A5: Option | B5: Command
A6: List available months | B6: python3 generate_owner_statements.py --list-months
A7: Generate all owners (June 2026) | B7: python3 generate_owner_statements.py --month 2026-06
A8: Generate one owner only | B8: python3 generate_owner_statements.py --month 2026-06 --owner VINEET
A9: Custom output folder | B9: python3 generate_owner_statements.py --month 2026-06 --output ./statements
A11: OUTPUT LOCATION
A12: PDFs are saved to: statements/YYYY-MM/YYYY-MM_OwnerName_statement.pdf
A14: EACH PDF INCLUDES
A15: • Trip details: LR, date, party, destination, truck, freight, commission, balance, PAHUNCH
A16: • Trip summary: totals for freight, commission, munsiyana, balance payable
A17: • Payments received that month
A18: • Account summary: balance payable − payments = net due

Sheet Pump Account
B1: HAMARA PUMP, KATRA — DIESEL ACCOUNT
B2: Track diesel deposits and usage per vehicle. Balance = Previous Balance + Deposit − Diesel − Cash.
B4: DATE | C4: Vehicle No. | D4: Deposit Amt. | E4: Diesel | F4: Cash | G4: Balance | H4: Notes
G5: =IF(D5="","",D5-E5-F5)
G6: =IF(B6="","",IF(G5="",0,G5)+D6-E6-F6)
G7: =IF(B7="","",IF(G6="",0,G6)+D7-E7-F7)
G8: =IF(B8="","",IF(G7="",0,G7)+D8-E8-F8)
G9: =IF(B9="","",IF(G8="",0,G8)+D9-E9-F9)
G10: =IF(B10="","",IF(G9="",0,G9)+D10-E10-F10)
G11: =IF(B11="","",IF(G10="",0,G10)+D11-E11-F11)
G12: =IF(B12="","",IF(G11="",0,G11)+D12-E12-F12)
G13: =IF(B13="","",IF(G12="",0,G12)+D13-E13-F13)
G14: =IF(B14="","",IF(G13="",0,G13)+D14-E14-F14)
G15: =IF(B15="","",IF(G14="",0,G14)+D15-E15-F15)
G16: =IF(B16="","",IF(G15="",0,G15)+D16-E16-F16)
G17: =IF(B17="","",IF(G16="",0,G16)+D17-E17-F17)
... G104: =IF(B104="","",IF(G103="",0,G103)+D104-E104-F104)

Sheet Master Data
A1: HARIOM LOGISTICS — MASTER DATA
A2: Parties!$A$5:$A$88 | C2: Destinations!$C$5:$C$100 | E2: Trucks!$E$5:$E$15 | J2: Owners!$J$5:$J$9 | L2: $L$5:$L$5 | P2: BillRefs!$P$5:$P$15
A3: PARTIES (Sold To) | C3: DESTINATIONS | E3: TRUCKS | J3: OWNERS | L3: STATUS LISTS | P3: TRIP BILL REFS
A4: Party Name | C4: Destination | E4: Truck No | F4: Owner | G4: Commission | H4: Munsiyana | J4: Owner Name | L4: PAHUNCH | M4: EPOD STATUS | N4: BILL STATUS | P4: Bill Ref
A5: ADARSH ENTERPRISES | C5: ALAPUR | E5: UP2525CT4515 | F5: BABU MISTRI | G5: 0 | H5: 0 | J5: BABU MISTRI | L5: YES | M5: YES | N5: PENDING | P5: 3
A6: AGARWAL CEMENT AGENCIES | C6: ALIGANJ (KHERI) | E6: UP25CT4514 | F6: BABU MISTRI | G6: 500 | H6: 100 | J6: MUKESH JI | M6: NO | N6: PASSED | P6: 5
A7: AGARWAL CEMENT and IRON SUPLIERS | C7: AMRITPUR | E7: UP25AT8981 | F7: MUKESH JI | G7: 500 | H7: 100 | J7: PAREEK JI | N7: PARTIAL | P7: 6
A8: AGARWAL TRADERS | C8: Amaur | E8: UP25BT7464 | F8: PAREEK JI | G8: 600 | H8: 100 | J8: SANDEEP | P8: 10
A9: AL HIND ENTERPRISES | C9: BAGHAULI | E9: UP25CT7099 | F9: PAREEK JI | G9: 600 | H9: 100 | J9: VINEET | P9: 11
A10: ALOK TRADERS | C10: BALLIA (SHJPUR) | E10: UP25DT1881 | F10: PAREEK JI | G10: 700 | H10: 100 | P10: 1 EPOD
A11: AMAN CEMENT STORE | C11: BANDA | E11: UP25DT5668 | F11: SANDEEP | G11: 400 | H11: 100 | P11: 2 EPOD
A12: ANKIT KUMAR VERMA | C12: BAREILLY | E12: UP25CT2572 | F12: VINEET | G12: 500 | H12: 100 | P12: 4 EPOD
A13: APNA KISHAN KENDRA | C13: BARKHAN | E13: UP25JT8802 | F13: VINEET | G13: 260 | H13: 50 | P13: 7 EPOD
A14: ASHOKA BUILDTECH | C14: BARKHERA JAIPAL | E14: UP25JT8803 | F14: VINEET | G14: 260 | H14: 50 | P14: 8 EPOD
A15: BAJPAI KHAD BHANDAR | C15: BASUDHARAN JAGIR | E15: UP25JT8804 | F15: VINEET | G15: 260 | H15: 50 | P15: 9 EPOD
A16: BHARAT BUILDERS | C16: BHAGWANTAPUR
A17: BHARAT FERTILIZERS (SIS) | C17: BHOJIPURA
A18: CEMENT HOUSE | C18: BHUTA
A19: CHAMPA LAL GUPTA AND SONS | C19: BILGRAM
A20: CHANDRA BUILDING MATERIAL | C20: BILSANDA
A21: CHAWLA ISPAT PVT LTD | C21: BILSI
A22: DEEP BUILDERS | C22: BISALPUR
A23: DUA AGENCIES | C23: BUDAUN
A24: DURGA BUILDING MATERIAL* | C24: CHANDAPUR
A25: Devha Firm | C25: CHHIBRAMAU
A26: GAFFAR CEMENT STORE | C26: DADIYA
A27: GANI ENTERPRISES | C27: DATAGANJ
... A88: VIJAY TRADERS | C88: SHAI
C89: SHERGARH (BLY)
C90: SHISHGARH
C91: SIKANDARABAD
C92: SINGHAI KALA
C93: SITAPUR
C94: TANDIYAWAN
C95: TILHAR
C96: TILMAS
C97: TISUA
C98: TUMURKHI
C99: Tikri
C100: UJHANI
